Workbook

Sheet REKAP 2 APRIL
A3: NO | B3: PRIORITAS DAERAH | C3: SASARAN DAERAH | D3: PROGRAM | E3: KEGIATAN PRIORITAS | F3: SASARAN KEGIATAN | G3: LOKASI (DESA/KEL) | I3: VOLUME | J3: PAGU USULAN AWAL | K3: PERANGKAT DAERAH PENANGGUNG JAWAB | L3: ID USULAN | M3: KECAMATAN | N3: HASIL PERBAIKAN KECAMATAN | P3: KETERANGAN
G4: DESA | H4: DUSUN | N4: VOL | O4: PAGU
A5: 1 | B5: 2 | C5: 3 | D5: 4 | E5: 5 | F5: 6 | G5: 7 | H5: 8 | I5: 9 | J5: 10 | K5: 11 | L5: 12 | M5: 13 | N5: 14 | O5: 15 | P5: 16
A6: =A5+1 -> 2 | B6: Infrastruktur Berkelanjutan | C6: Meningkatnya Ketahanan Daerah terhadap Bencana | D6: PROGRAM PENANGGULANGAN BENCANA | E6: Pembangunan Sumur Bor | F6: Masyarakat Dusun Karang Duntal | G6: GERIMAX INDAH | H6: KARANG DUNTAL | I6: 1 unit | J6: 100000000 | K6: Badan Penanggulangan Bencana Daerah | L6: 2799328 | M6: Narmada | N6: 1 paket | O6: 210000000 | P6: Dilengkapi dengan usulan Proposal
A7: =A6+1 -> 3 | B7: Infrastruktur Berkelanjutan | C7: Meningkatnya Ketahanan Daerah terhadap Bencana | D7: PROGRAM PENANGGULANGAN BENCANA | E7: Pembangunan Sumur Bor | F7: Masyarakat Dusun Karang Anyar | G7: GERIMAX INDAH | H7: KARANG ANYAR (GERIMAX INDAH) | I7: 1 unit | J7: 100000000 | K7: Badan Penanggulangan Bencana Daerah | L7: 2799328 | M7: Narmada | N7: 1 paket | O7: 210000000 | P7: Dilengkapi dengan usulan Proposal
A8: =A7+1 -> 4 | B8: Infrastruktur Berkelanjutan | C8: Meningkatnya Ketahanan Daerah terhadap Bencana | D8: PROGRAM PENANGGULANGAN BENCANA | E8: PENANGGULANGAN BENCANA | F8: Pelatihan Relawan Kebencanaan | G8: Gerimax Indah | H8: =H3 -> 0 | I8: 1 Paket | J8: 7500000 | K8: Badan Penanggulangan Bencana Daerah | M8: Narmada | N8: 1 paket | O8: 35000000 | P8: Pindahan dari Pol PP
A9: =A8+1 -> 5 | B9: Infrastruktur Berkelanjutan | C9: Meningkatnya pembangunan Infrastruktur Dasar dan Konektivitas Antar Wilayah | D9: PROGRAM PENANGGULANGAN BENCANA | E9: PENGADAAN SUMUR BOR dan Intalasinya | F9: Masyarakat Dusun Lekong Siwak | G9: TANAK BEAK | H9: LEKONG SIWAK | I9: 1 | J9: 200000000 | K9: Badan Penanggulangan Bencana Daerah | L9: 2934710 | M9: Narmada | N9: 1 | O9: 210000000 | P9: sumur bor
A10: =A9+1 -> 6 | B10: Infrastruktur Berkelanjutan | C10: Meningkatnya Ketahanan Daerah terhadap Bencana | D10: PROGRAM PENANGGULANGAN BENCANA | E10: Pemasangan Jalur Evakuasi dan papan Informasi Bencana | G10: BAGIK POLAK BARAT | H10: LENDANG | I10: 1 Paket | J10: 5000000 | K10: Badan Penanggulangan Bencana Daerah | L10: 2932750 | M10: Labuapi | N10: 1 paket | O10: 25000000
A11: =A10+1 -> 7 | B11: Infrastruktur Berkelanjutan | C11: Meningkatnya Ketahanan Daerah terhadap Bencana | D11: PROGRAM PENANGGULANGAN BENCANA | E11: Pelatihan Relawan Kebencanaan | F11: - | G11: Karang Bongkot | H11: Karang Bongkot | I11: 1 Paket | J11: 7500000 | K11: Badan Penanggulangan Bencana Daerah | L11: 2819724 | M11: Labuapi | N11: 1 paket | O11: 35000000
A12: =#REF!+1 -> #REF! | B12: Infrastruktur Berkelanjutan | C12: Meningkatnya Ketahanan Daerah terhadap Bencana | D12: PROGRAM PENANGGULANGAN BENCANA | E12: Pengadaan sumur bor dan jaringan instalasinya untuk daerah rawan kekeringan | F12: Masyarakat Dusun Lendang Bontong | G12: SEKOTONG TENGAH | H12: LENDANG BONTONG | I12: 2 Unit | J12: 100000000 | K12: Badan Penanggulangan Bencana Daerah | L12: 2966626 | M12: Sekotong | N12: 1 pkt | O12: 210000000 | P12: dilengkapi dengan proposal
A13: =A12+1 -> #REF! | B13: Infrastruktur Berkelanjutan | C13: Meningkatnya Ketahanan Daerah terhadap Bencana | D13: PROGRAM PENANGGULANGAN BENCANA | E13: Pengadaan sumur bor dan jaringan instalasinya untuk daerah rawan kekeringan | F13: Masyarakat Dusun Montong Bao | G13: KEDARO | H13: MONTONG BAO | I13: 2 Paket | J13: 100000000 | K13: Badan Penanggulangan Bencana Daerah | L13: _ | M13: Sekotong | N13: 1 pkt | O13: 210000000 | P13: Pindahan dari DPUPRPKM
A14: =A13+1 -> #REF! | B14: Infrastruktur Berkelanjutan | C14: Meningkatnya Ketahanan Daerah terhadap Bencana | D14: PROGRAM PENANGGULANGAN BENCANA | E14: Pengadaan sumur bor dan jaringan instalasinya untuk daerah rawan kekeringan | F14: Masyarakat Dusun medames | G14: KEDARO | H14: MEDAMES | I14: 2 Paket | J14: 100000000 | K14: Badan Penanggulangan Bencana Daerah | L14: _ | M14: Sekotong | N14: 1 pkt | O14: 210000000 | P14: Pindahan dari DPUPRPKM
A15: =A14+1 -> #REF! | B15: Infrastruktur Berkelanjutan | C15: Meningkatnya Ketahanan Daerah terhadap Bencana | D15: PROGRAM PENANGGULANGAN BENCANA | E15: Pengadaan sumur bor dan jaringan instalasinya untuk daerah rawan kekeringan | F15: Masyarakat Dusun Mendawe Utara | G15: KEDARO | H15: MENDAWE UTARA | I15: 2 Paket | J15: 100000000 | K15: Badan Penanggulangan Bencana Daerah | L15: _ | M15: Sekotong | N15: 1 pkt | O15: 210000000 | P15: Pindahan dari DPUPRPKM
A16: 15 | B16: Infrastruktur Berkelanjutan | C16: Meningkatnya Ketahanan Daerah terhadap Bencana | D16: PROGRAM PENANGGULANGAN BENCANA | E16: Pengadaan sumur bor dan jaringan instalasinya untuk daerah rawan kekeringan | G16: Selat | H16: Montong Daye | K16: Badan Penanggulangan Bencana Daerah | M16: Narmada | N16: 1 pkt | O16: 210000000 | P16: Ada di BA Musrenbang Kab, pindahan PUPR
A17: 1 | B17: Transformasi dan Kemandirian Ekonomi | C17: Terjaganya stabilitas inflasi | D17: PROGRAM PENINGKATAN SARANA DISTRIBUSI PERDAGANGAN | E17: Pengadaan Rombong Roda beratap 50 Paket dan penataan UMKM | F17: Kelompok UMKM pada Dusun Senggigi | G17: SENGGIGI | H17: SENGGIGI | I17: 50 Paket | J17: 50000000 | K17: Dinas Perdagangan | L17: 2818477 | M17: Batulayar | N17: 8 | O17: 50760000
A18: 2 | B18: Transformasi dan Kemandirian Ekonomi | C18: Terjaganya stabilitas inflasi | D18: PROGRAM PENINGKATAN SARANA DISTRIBUSI PERDAGANGAN | E18: Bantuan Sarpras UMKM ( Rombong, Tenda Stand, Meja, Kursi ) | F18: Kelompok UMKM yang ada pada Desa senteluk Daye | G18: SENTELUK | H18: PENYANGGET | I18: 10 paket | J18: 200000000 | K18: Dinas Perdagangan | L18: 2817507 | M18: Batulayar | N18: 32 | O18: 203040000
A19: 3 | B19: Transformasi dan Kemandirian Ekonomi | C19: Terjaganya stabilitas inflasi | D19: PROGRAM PENINGKATAN SARANA DISTRIBUSI PERDAGANGAN | E19: Bantuan Sarana dan Prasarana Perdagangan | F19: Kelompok UMKM desa sandik | G19: Sandik | H19: ??? | I19: 4 paket | J19: 20000000 | K19: Dinas Perdagangan | L19: 3299586 | M19: Batulayar | N19: 3 | O19: 20000000 | P19: Pindahan Diskop
A20: 4 | B20: Transformasi dan Kemandirian Ekonomi | C20: Terjaganya stabilitas inflasi | D20: PROGRAM PENINGKATAN SARANA DISTRIBUSI PERDAGANGAN | E20: Grobak UMKM | F20: Masyarakat Dusun Penimbung Barat | G20: PENIMBUNG | H20: PENIMBUNG BARAT | I20: 3 UNIT | J20: 18000000 | K20: Dinas Perdagangan | L20: 3299071 | M20: Gunung Sari | N20: 3 | O20: =N20*6345000 -> 19035000 | P20: pindahan dari provinsi
A21: 5 | B21: Transformasi dan Kemandirian Ekonomi | C21: Terjaganya stabilitas inflasi | D21: PROGRAM PENINGKATAN SARANA DISTRIBUSI PERDAGANGAN | E21: Grobak UMKM | F21: Masyarakat Dusun Bukit Tinggi | G21: BUKIT TINGGI | H21: BUKIT TINGGI | I21: 5 kelompok | J21: 50000000 | K21: Dinas Perdagangan | L21: 3299835 | M21: Gunung Sari | N21: 8 | O21: 50760000 | P21: pindahan dari Disperinkop
A22: 6 | B22: Transformasi dan Kemandirian Ekonomi | C22: Terjaganya stabilitas inflasi | D22: PROGRAM PENINGKATAN SARANA DISTRIBUSI PERDAGANGAN | E22: Bantuan Gerobak,Etalase dan Tenda untuk pedagang sate bulayak dusun karang mas | F22: Kelompok Dagang Sate Karang Mas | G22: Batu Kumbung | H22: Karang Mas | I22: 1 Paket | J22: 100000000 | K22: Dinas Perdagangan | L22: 2792437 | M22: Lingsar | N22: 7 | O22: 100000000 | P22: GEROBAK (7 unit Rp 44.415.000), Tenda (7 unit Rp41.300.000), Etalase (7 uni Rp 14.000.000)
A23: 7 | B23: Transformasi dan Kemandirian Ekonomi | C23: Terjaganya stabilitas inflasi | D23: PROGRAM PENINGKATAN SARANA DISTRIBUSI PERDAGANGAN | E23: Bantuan Sarana dan Prasarana Perdagangan | F23: Masyarakat Desa | G23: LINGSAR | H23: LINGSAR TAMAN | I23: 50 Bh | J23: 300000000 | K23: Dinas Perdagangan | L23: 2952867 | M23: Lingsar | N23: 21 | O23: 315000000 | P23: GEROBAK (7 unit Rp 44.415.000), Tenda (7 unit Rp41.300.000), Etalase (7 uni Rp 14.000.000)
A24: 8 | B24: Transformasi dan Kemandirian Ekonomi | C24: Terjaganya stabilitas inflasi | D24: PROGRAM PENINGKATAN SARANA DISTRIBUSI PERDAGANGAN | E24: Bantuan Sarana dan Prasarana Perdagangan | F24: Kelompok Pedagang | G24: BUG-BUG | H24: BUG-BUG UTARA TIMUR | I24: 3 KELOMPOK | J24: 15000000 | K24: Dinas Perdagangan | L24: 2921906 | M24: Lingsar | N24: 2 | O24: 14690000 | P24: gerobak (2 unit Rp 12.690.000), Etalase P. 150X40X110 (1 unit Rp 2.000.000)
A25: 9 | B25: Transformasi dan Kemandirian Ekonomi | C25: Terjaganya stabilitas inflasi | D25: PROGRAM PENINGKATAN SARANA DISTRIBUSI PERDAGANGAN | E25: Bantuan Sarana dan Prasarana Perdagangan | F25: Kelompok Pedagang | G25: BUG-BUG | H25: BUG-BUG SELATAN | I25: 3 KELOMPOK | J25: 15000000 | K25: Dinas Perdagangan | L25: 2921825 | M25: Lingsar | N25: 2 | O25: 14690000 | P25: gerobak (2 unit Rp 12.690.000), Etalase P. 150X40X110 (1 unit Rp 2.000.000)
A26: 10 | B26: Transformasi dan Kemandirian Ekonomi | C26: Terjaganya stabilitas inflasi | D26: PROGRAM PENINGKATAN SARANA DISTRIBUSI PERDAGANGAN | E26: BANTUAN SARANA DAN PRASARANA PERDAGANGAN GEROBAK | F26: Masyarakat Dusun Karang Duntal | G26: GERIMAX INDAH | H26: KARANG DUNTAL | I26: 2 unit | J26: 10000000 | K26: Dinas Perdagangan | L26: 3307589 | M26: Narmada | N26: 12 | O26: 76140000 | P26: OPERAN PERINKOP
A27: 11 | B27: Transformasi dan Kemandirian Ekonomi | C27: Terjaganya stabilitas inflasi | D27: PROGRAM PENINGKATAN SARANA DISTRIBUSI PERDAGANGAN | E27: BANTUAN SARANA DAN PRASARANA PERDAGANGAN GEROBAK | F27: Masyarakat Dusun Kembang Kuning | G27: GERIMAX INDAH | H27: KEMBANG KUNING | I27: 15 unit | J27: 10000000 | K27: Dinas Perdagangan | L27: 3307611 | M27: Narmada | N27: 15 | O27: =15*6345000 -> 95175000 | P27: OPERAN PERINKOP
A28: 12 | B28: Transformasi dan Kemandirian Ekonomi | C28: Terjaganya stabilitas inflasi | D28: PROGRAM PENINGKATAN SARANA DISTRIBUSI PERDAGANGAN | E28: BANTUAN SARANA DAN PRASARANA PERDAGANGAN GEROBAK | F28: Masyarakat Dusun Karang Anyar | G28: GERIMAX INDAH | H28: KARANG ANYAR (GERIMAX INDAH) | I28: 2 unit | J28: 10000000 | K28: Dinas Perdagangan | L28: 3245837 | M28: Narmada | N28: 2 | O28: =2*6345000 -> 12690000 | P28: OPERAN PERINKOP
A29: 13 | B29: Transformasi dan Kemandirian Ekonomi | C29: Terjaganya stabilitas inflasi | D29: PROGRAM PENINGKATAN SARANA DISTRIBUSI PERDAGANGAN | E29: BANTUAN SARANA DAN PRASARANA PERDAGANGAN GEROBAK | F29: Masyarakat Dusun Dasan Montor | G29: GERIMAX INDAH | H29: DASAN MONTOR | I29: 4 unit | J29: 10000000 | K29: Dinas Perdagangan | L29: 3307634 | M29: Narmada | N29: 12 | O29: 76140000 | P29: OPERAN PERINKOP
A30: 14 | B30: Transformasi dan Kemandirian Ekonomi | C30: Terjaganya stabilitas inflasi | D30: PROGRAM PENINGKATAN SARANA DISTRIBUSI PERDAGANGAN | E30: BANTUAN SARANA DAN PRASARANA PERDAGANGAN GEROBAK | G30: SELAT | H30: SELAT BARAT | I30: 4 unit | J30: 25000000 | K30: Dinas Perdagangan | L30: 3307657 | M30: Narmada | N30: 4 | O30: 25380000 | P30: OPERAN PERINKOP
A31: 15 | B31: Transformasi dan Kemandirian Ekonomi | C31: Terjaganya stabilitas inflasi | D31: PROGRAM PENINGKATAN SARANA DISTRIBUSI PERDAGANGAN | E31: BANTUAN SARANA DAN PRASARANA PERDAGANGAN GEROBAK | G31: SELAT | H31: SELAT TIMUR | I31: 10 Unit Gerobak | J31: 25000000 | K31: Dinas Perdagangan | L31: 3307667 | M31: Narmada | N31: 4 | O31: 25380000 | P31: OPERAN PERINKOP
A32: 16 | B32: Transformasi dan Kemandirian Ekonomi | C32: Terjaganya stabilitas inflasi | D32: PROGRAM PENINGKATAN SARANA DISTRIBUSI PERDAGANGAN | E32: Bantuan Sarana dan Prasarana Perdagangan | F32: Warga Dusun Bangket Punik, Desa Golong | G32: GOLONG | H32: BANGKET PUNIK | I32: 2 unit | J32: 100000000 | K32: Dinas Perdagangan | L32: 2906025 | M32: Narmada | N32: 16 | O32: 101520000
A33: 17 | B33: Transformasi dan Kemandirian Ekonomi | C33: Terjaganya stabilitas inflasi | D33: PROGRAM PENINGKATAN SARANA DISTRIBUSI PERDAGANGAN | E33: BANTUAN SARANA DAN PRASARANA PERDAGANGAN GEROBAK | F33: UMKM Dusun Golong, Desa Golong | G33: GOLONG | H33: Golong | I33: 10 Unit Gerobak | J33: 100000000 | K33: Dinas Perdagangan | L33: 3307681 | M33: Narmada | N33: 16 | O33: 101520000
A34: 18 | B34: Transformasi dan Kemandirian Ekonomi | C34: Terjaganya stabilitas inflasi | D34: PROGRAM PENINGKATAN SARANA DISTRIBUSI PERDAGANGAN | E34: Banyak Umkm di desa Lelede yang memerlukan sarana dan prasarana berupa RAK untuk menunjang Kreativitas usahanya (Jadi Etalase) | F34: Masyarakat Dusun setempat | G34: LELEDE | H34: DASAN BAWAK | I34: 6 UNIT | J34: 30000000 | K34: Dinas Perdagangan | L34: 3304126 | M34: Kediri | N34: 12 UNIT | O34: 50000000 | P34: OPERAN DISKOP (ETALASE)
A35: 19 | B35: Transformasi dan Kemandirian Ekonomi | C35: Terjaganya stabilitas inflasi | D35: PROGRAM PENINGKATAN SARANA DISTRIBUSI PERDAGANGAN | E35: Sarana Perdagangan BUMDES desa Gelogor (boxshop) | F35: masyarakat setempat | G35: GELOGOR | H35: GELOGOR SELATAN | I35: 10 unit | J35: 100000000 | K35: Dinas Perdagangan | L35: 3304037 | M35: Kediri | N35: 10 | O35: 100000000 | P35: OPERAN BPMD
A36: 20 | B36: Transformasi dan Kemandirian Ekonomi | C36: Terjaganya stabilitas inflasi | D36: PROGRAM PENINGKATAN SARANA DISTRIBUSI PERDAGANGAN | E36: Kurangnya Alat-Alat dagang bagi pengusaha kecil menegah seperti(Gerobak dan lain lain) | F36: Masyarakat Dusun setempat | G36: BANYUMULEK | H36: DASAN TAWAR | I36: 3 UNIT | J36: 20000000 | K36: Dinas Perdagangan | L36: 3304169 | M36: Kediri | N36: 3 | O36: 19035000
A37: 21 | B37: Transformasi dan Kemandirian Ekonomi | C37: Terjaganya stabilitas inflasi | D37: PROGRAM PENINGKATAN SARANA DISTRIBUSI PERDAGANGAN | E37: banyak Umkm di desa Ombe baru yang memerluka sarana dan prasarana untuk menunjang usahanya (Grobak) | F37: Masyarakat Dusun setempat | G37: OMBE BARU | H37: OMBE BEBAE DAN OMBE DESE | I37: 2x0,80 | J37: 40000000 | K37: Dinas Perdagangan | L37: 2871327 | M37: Kediri | N37: 6 | O37: 38000000
A38: 22 | B38: Transformasi dan Kemandirian Ekonomi | C38: Terjaganya stabilitas inflasi | D38: PROGRAM PENINGKATAN SARANA DISTRIBUSI PERDAGANGAN | E38: Bantuan Sarana dan Prasarana Perdagangan | G38: BAGIK POLAK BARAT | H38: JOGOT SELATAN | I38: 1 paket | J38: 8000000 | K38: Dinas Perdagangan | L38: 2933174 | M38: Labuapi | N38: 1 | O38: 8000000
A39: 23 | B39: Transformasi dan Kemandirian Ekonomi | C39: Terjaganya stabilitas inflasi | D39: PROGRAM PENINGKATAN SARANA DISTRIBUSI PERDAGANGAN | E39: Bantuan Sarana dan Prasarana Perdagangan | G39: Bajur | H39: BAJUR AMPEL | I39: 5 Unit | J39: 25000000 | K39: Dinas Perdagangan | L39: 2914087 | M39: Labuapi | N39: 28 | O39: 177660000 | P39: PAGU BERUBAH (GEROBAK)
A40: 24 | B40: Transformasi dan Kemandirian Ekonomi | C40: Terjaganya stabilitas inflasi | D40: PROGRAM PENINGKATAN SARANA DISTRIBUSI PERDAGANGAN | E40: Bantuan Sarana dan Prasarana Perdagangan | F40: Kelompok . . | G40: Perampuan | H40: PERAMPUAN BARAT | I40: 5 unit | J40: 50000000 | K40: Dinas Perdagangan | L40: 2872813 | M40: Labuapi | N40: 8 | O40: 50760000
A41: 25 | B41: Transformasi dan Kemandirian Ekonomi | C41: Terjaganya stabilitas inflasi | D41: PROGRAM PENINGKATAN SARANA DISTRIBUSI PERDAGANGAN | E41: Permohonan Bantuan Sarana Usaha (Gerobak) UMKM | F41: Masyarakat Dusun setempat | G41: JAGARAGA | H41: DASAN GERES | I41: 1 Paket | J41: 50000000 | K41: Dinas Perdagangan | L41: 3310300 | M41: Kuripan | N41: 10 | O41: 63450000 | P41: GEROBAK
A42: 26 | B42: Transformasi dan Kemandirian Ekonomi | C42: Terjaganya stabilitas inflasi | D42: PROGRAM PENINGKATAN SARANA DISTRIBUSI PERDAGANGAN | E42: Gerobak UMKM | F42: Kelompok UMKM | G42: JEMBATAN GANTUNG | H42: TELUK SEPANG | I42: 4 UNIT | J42: 25000000 | K42: Dinas Perdagangan | L42: 3307568 | M42: Lembar | N42: 4 | O42: 25380000 | P42: OPERAN PERINKOP
...

Sheet OPD_KEC_musrenbang
A1: REKAP PER OPD_KECAMATAN USULAN DESA TAHUN 2027 (FORUM PERANGKAT DAERAH)
A2: Rekap Tanggal 3 April 2026
A3: NO | B3: OPD TUJUAN | C3: Batulayar | D3: Gerung | E3: GUNUNG SARI | F3: Kediri | G3: Kuripan | H3: Labuapi | I3: Lembar | J3: Lingsar | K3: Narmada | L3: Sekotong | M3: JUMLAH | N3: PAGU TOTAL OPD | O3: PROGRAM PENUNJANG | P3: PAGU CORE BISNIS | Q3: SELISIH PAGU COR BISNIS DGN USULAN DESA
A4: 1 | B4: Badan Kesatuan Bangsa dan Politik | M4: =SUM(C4:L4) -> 0 | N4: 8867508178 | O4: 4442008178 | P4: =N4-O4 -> 4425500000 | Q4: =P4-M4 -> 4425500000
A5: =A4+1 -> 2 | B5: Dinas Kearsipan dan Perpustakaan | C5: =SUMIFS('[1]REKAP MUSRENKAB 17 MARET'!$Q$6:$Q$1488,'[1]REKAP MUSRENKAB 17 MARET'!$K$6:$K$1488,B5,'[1]REKAP MUSRENKAB 17 MARET'!$O$6:$O$1488,$C$3) -> 0 | D5: =SUMIFS('[1]REKAP MUSRENKAB 17 MARET'!$Q$6:$Q$1488,'[1]REKAP MUSRENKAB 17 MARET'!$K$6:$K$1488,B5,'[1]REKAP MUSRENKAB 17 MARET'!$O$6:$O$1488,$D$3) -> 0 | E5: =SUMIFS('[1]REKAP MUSRENKAB 17 MARET'!$Q$6:$Q$1488,'[1]REKAP MUSRENKAB 17 MARET'!$K$6:$K$1488,B5,'[1]REKAP MUSRENKAB 17 MARET'!$O$6:$O$1488,$E$3) -> 0 | F5: =SUMIFS('[1]REKAP MUSRENKAB 17 MARET'!$Q$6:$Q$1488,'[1]REKAP MUSRENKAB 17 MARET'!$K$6:$K$1488,B5,'[1]REKAP MUSRENKAB 17 MARET'!$O$6:$O$1488,$F$3) -> 0 | G5: =SUMIFS('[1]REKAP MUSRENKAB 17 MARET'!$Q$6:$Q$1488,'[1]REKAP MUSRENKAB 17 MARET'!$K$6:$K$1488,B5,'[1]REKAP MUSRENKAB 17 MARET'!$O$6:$O$1488,$G$3) -> 0 | H5: =SUMIFS('[1]REKAP MUSRENKAB 17 MARET'!$Q$6:$Q$1488,'[1]REKAP MUSRENKAB 17 MARET'!$K$6:$K$1488,B5,'[1]REKAP MUSRENKAB 17 MARET'!$O$6:$O$1488,$H$3) -> 0 | I5: =SUMIFS('[1]REKAP MUSRENKAB 17 MARET'!$Q$6:$Q$1488,'[1]REKAP MUSRENKAB 17 MARET'!$K$6:$K$1488,B5,'[1]REKAP MUSRENKAB 17 MARET'!$O$6:$O$1488,$I$3) -> 0 | J5: =SUMIFS('[1]REKAP MUSRENKAB 17 MARET'!$Q$6:$Q$1488,'[1]REKAP MUSRENKAB 17 MARET'!$K$6:$K$1488,B5,'[1]REKAP MUSRENKAB 17 MARET'!$O$6:$O$1488,$J$3) -> 0 | K5: =SUMIFS('[1]REKAP MUSRENKAB 17 MARET'!$Q$6:$Q$1488,'[1]REKAP MUSRENKAB 17 MARET'!$K$6:$K$1488,B5,'[1]REKAP MUSRENKAB 17 MARET'!$O$6:$O$1488,$K$3) -> 0 | L5: =SUMIFS('[1]REKAP MUSRENKAB 17 MARET'!$Q$6:$Q$1488,'[1]REKAP MUSRENKAB 17 MARET'!$K$6:$K$1488,B5,'[1]REKAP MUSRENKAB 17 MARET'!$O$6:$O$1488,$L$3) -> 0 | M5: =SUM(C5:L5) -> 0 | P5: =N5-O5 -> 0 | Q5: =P5-M5 -> 0
A6: =A5+1 -> 3 | B6: Dinas Kesehatan, Pengendalian Penduduk dan Keluarga Berencana | C6: =SUMIFS('[1]REKAP MUSRENKAB 17 MARET'!$Q$6:$Q$1488,'[1]REKAP MUSRENKAB 17 MARET'!$K$6:$K$1488,B6,'[1]REKAP MUSRENKAB 17 MARET'!$O$6:$O$1488,$C$3) -> 0 | D6: =SUMIFS('[1]REKAP MUSRENKAB 17 MARET'!$Q$6:$Q$1488,'[1]REKAP MUSRENKAB 17 MARET'!$K$6:$K$1488,B6,'[1]REKAP MUSRENKAB 17 MARET'!$O$6:$O$1488,$D$3) -> 0 | E6: =SUMIFS('[1]REKAP MUSRENKAB 17 MARET'!$Q$6:$Q$1488,'[1]REKAP MUSRENKAB 17 MARET'!$K$6:$K$1488,B6,'[1]REKAP MUSRENKAB 17 MARET'!$O$6:$O$1488,$E$3) -> 0 | F6: =SUMIFS('[1]REKAP MUSRENKAB 17 MARET'!$Q$6:$Q$1488,'[1]REKAP MUSRENKAB 17 MARET'!$K$6:$K$1488,B6,'[1]REKAP MUSRENKAB 17 MARET'!$O$6:$O$1488,$F$3) -> 0 | G6: =SUMIFS('[1]REKAP MUSRENKAB 17 MARET'!$Q$6:$Q$1488,'[1]REKAP MUSRENKAB 17 MARET'!$K$6:$K$1488,B6,'[1]REKAP MUSRENKAB 17 MARET'!$O$6:$O$1488,$G$3) -> 0 | H6: =SUMIFS('[1]REKAP MUSRENKAB 17 MARET'!$Q$6:$Q$1488,'[1]REKAP MUSRENKAB 17 MARET'!$K$6:$K$1488,B6,'[1]REKAP MUSRENKAB 17 MARET'!$O$6:$O$1488,$H$3) -> 752840000 | I6: =SUMIFS('[1]REKAP MUSRENKAB 17 MARET'!$Q$6:$Q$1488,'[1]REKAP MUSRENKAB 17 MARET'!$K$6:$K$1488,B6,'[1]REKAP MUSRENKAB 17 MARET'!$O$6:$O$1488,$I$3) -> 0 | J6: =SUMIFS('[1]REKAP MUSRENKAB 17 MARET'!$Q$6:$Q$1488,'[1]REKAP MUSRENKAB 17 MARET'!$K$6:$K$1488,B6,'[1]REKAP MUSRENKAB 17 MARET'!$O$6:$O$1488,$J$3) -> 0 | K6: =SUMIFS('[1]REKAP MUSRENKAB 17 MARET'!$Q$6:$Q$1488,'[1]REKAP MUSRENKAB 17 MARET'!$K$6:$K$1488,B6,'[1]REKAP MUSRENKAB 17 MARET'!$O$6:$O$1488,$K$3) -> 25830000 | L6: =SUMIFS('[1]REKAP MUSRENKAB 17 MARET'!$Q$6:$Q$1488,'[1]REKAP MUSRENKAB 17 MARET'!$K$6:$K$1488,B6,'[1]REKAP MUSRENKAB 17 MARET'!$O$6:$O$1488,$L$3) -> 0 | M6: =SUM(C6:L6) -> 778670000 | N6: 699757253403 | O6: 324873540000 | P6: =N6-O6 -> 374883713403 | Q6: =P6-M6 -> 374105043403
A7: =A6+1 -> 4 | B7: Dinas Kelautan, Perikanan, dan Ketahanan Pangan | C7: =SUMIFS('[1]REKAP MUSRENKAB 17 MARET'!$Q$6:$Q$1488,'[1]REKAP MUSRENKAB 17 MARET'!$K$6:$K$1488,B7,'[1]REKAP MUSRENKAB 17 MARET'!$O$6:$O$1488,$C$3) -> 140000000 | D7: =SUMIFS('[1]REKAP MUSRENKAB 17 MARET'!$Q$6:$Q$1488,'[1]REKAP MUSRENKAB 17 MARET'!$K$6:$K$1488,B7,'[1]REKAP MUSRENKAB 17 MARET'!$O$6:$O$1488,$D$3) -> 0 | E7: =SUMIFS('[1]REKAP MUSRENKAB 17 MARET'!$Q$6:$Q$1488,'[1]REKAP MUSRENKAB 17 MARET'!$K$6:$K$1488,B7,'[1]REKAP MUSRENKAB 17 MARET'!$O$6:$O$1488,$E$3) -> 178000000 | F7: =SUMIFS('[1]REKAP MUSRENKAB 17 MARET'!$Q$6:$Q$1488,'[1]REKAP MUSRENKAB 17 MARET'!$K$6:$K$1488,B7,'[1]REKAP MUSRENKAB 17 MARET'!$O$6:$O$1488,$F$3) -> 0 | G7: =SUMIFS('[1]REKAP MUSRENKAB 17 MARET'!$Q$6:$Q$1488,'[1]REKAP MUSRENKAB 17 MARET'!$K$6:$K$1488,B7,'[1]REKAP MUSRENKAB 17 MARET'!$O$6:$O$1488,$G$3) -> 0 | H7: =SUMIFS('[1]REKAP MUSRENKAB 17 MARET'!$Q$6:$Q$1488,'[1]REKAP MUSRENKAB 17 MARET'!$K$6:$K$1488,B7,'[1]REKAP MUSRENKAB 17 MARET'!$O$6:$O$1488,$H$3) -> 60000000 | I7: =SUMIFS('[1]REKAP MUSRENKAB 17 MARET'!$Q$6:$Q$1488,'[1]REKAP MUSRENKAB 17 MARET'!$K$6:$K$1488,B7,'[1]REKAP MUSRENKAB 17 MARET'!$O$6:$O$1488,$I$3) -> 25000000 | J7: =SUMIFS('[1]REKAP MUSRENKAB 17 MARET'!$Q$6:$Q$1488,'[1]REKAP MUSRENKAB 17 MARET'!$K$6:$K$1488,B7,'[1]REKAP MUSRENKAB 17 MARET'!$O$6:$O$1488,$J$3) -> 0 | K7: =SUMIFS('[1]REKAP MUSRENKAB 17 MARET'!$Q$6:$Q$1488,'[1]REKAP MUSRENKAB 17 MARET'!$K$6:$K$1488,B7,'[1]REKAP MUSRENKAB 17 MARET'!$O$6:$O$1488,$K$3) -> 0 | L7: =SUMIFS('[1]REKAP MUSRENKAB 17 MARET'!$Q$6:$Q$1488,'[1]REKAP MUSRENKAB 17 MARET'!$K$6:$K$1488,B7,'[1]REKAP MUSRENKAB 17 MARET'!$O$6:$O$1488,$L$3) -> 140000000 | M7: =SUM(C7:L7) -> 543000000 | N7: 21091507877 | O7: 9331186759 | P7: =N7-O7 -> 11760321118 | Q7: =P7-M7 -> 11217321118
A8: =A7+1 -> 5 | B8: Dinas Perindustrian, Koperasi, Usaha Kecil dan Menengah, dan Tenaga Kerja | C8: =SUMIFS('[1]REKAP MUSRENKAB 17 MARET'!$Q$6:$Q$1488,'[1]REKAP MUSRENKAB 17 MARET'!$K$6:$K$1488,B8,'[1]REKAP MUSRENKAB 17 MARET'!$O$6:$O$1488,$C$3) -> 181000000 | D8: =SUMIFS('[1]REKAP MUSRENKAB 17 MARET'!$Q$6:$Q$1488,'[1]REKAP MUSRENKAB 17 MARET'!$K$6:$K$1488,B8,'[1]REKAP MUSRENKAB 17 MARET'!$O$6:$O$1488,$D$3) -> 155000000 | E8: =SUMIFS('[1]REKAP MUSRENKAB 17 MARET'!$Q$6:$Q$1488,'[1]REKAP MUSRENKAB 17 MARET'!$K$6:$K$1488,B8,'[1]REKAP MUSRENKAB 17 MARET'!$O$6:$O$1488,$E$3) -> 416400000 | F8: =SUMIFS('[1]REKAP MUSRENKAB 17 MARET'!$Q$6:$Q$1488,'[1]REKAP MUSRENKAB 17 MARET'!$K$6:$K$1488,B8,'[1]REKAP MUSRENKAB 17 MARET'!$O$6:$O$1488,$F$3) -> 135000000 | G8: =SUMIFS('[1]REKAP MUSRENKAB 17 MARET'!$Q$6:$Q$1488,'[1]REKAP MUSRENKAB 17 MARET'!$K$6:$K$1488,B8,'[1]REKAP MUSRENKAB 17 MARET'!$O$6:$O$1488,$G$3) -> 646511000 | H8: =SUMIFS('[1]REKAP MUSRENKAB 17 MARET'!$Q$6:$Q$1488,'[1]REKAP MUSRENKAB 17 MARET'!$K$6:$K$1488,B8,'[1]REKAP MUSRENKAB 17 MARET'!$O$6:$O$1488,$H$3) -> 382450000 | I8: =SUMIFS('[1]REKAP MUSRENKAB 17 MARET'!$Q$6:$Q$1488,'[1]REKAP MUSRENKAB 17 MARET'!$K$6:$K$1488,B8,'[1]REKAP MUSRENKAB 17 MARET'!$O$6:$O$1488,$I$3) -> 151500000 | J8: =SUMIFS('[1]REKAP MUSRENKAB 17 MARET'!$Q$6:$Q$1488,'[1]REKAP MUSRENKAB 17 MARET'!$K$6:$K$1488,B8,'[1]REKAP MUSRENKAB 17 MARET'!$O$6:$O$1488,$J$3) -> 36000000 | K8: =SUMIFS('[1]REKAP MUSRENKAB 17 MARET'!$Q$6:$Q$1488,'[1]REKAP MUSRENKAB 17 MARET'!$K$6:$K$1488,B8,'[1]REKAP MUSRENKAB 17 MARET'!$O$6:$O$1488,$K$3) -> 304500000 | L8: =SUMIFS('[1]REKAP MUSRENKAB 17 MARET'!$Q$6:$Q$1488,'[1]REKAP MUSRENKAB 17 MARET'!$K$6:$K$1488,B8,'[1]REKAP MUSRENKAB 17 MARET'!$O$6:$O$1488,$L$3) -> 160000000 | M8: =SUM(C8:L8) -> 2568361000 | N8: 25392059315 | O8: 10542461515 | P8: =N8-O8 -> 14849597800 | Q8: =P8-M8 -> 12281236800
A9: =A8+1 -> 6 | B9: Dinas Pariwisata, Ekonomi Kreatif, Pemuda, dan Olahraga | C9: =SUMIFS('[1]REKAP MUSRENKAB 17 MARET'!$Q$6:$Q$1488,'[1]REKAP MUSRENKAB 17 MARET'!$K$6:$K$1488,B9,'[1]REKAP MUSRENKAB 17 MARET'!$O$6:$O$1488,$C$3) -> 0 | D9: =SUMIFS('[1]REKAP MUSRENKAB 17 MARET'!$Q$6:$Q$1488,'[1]REKAP MUSRENKAB 17 MARET'!$K$6:$K$1488,B9,'[1]REKAP MUSRENKAB 17 MARET'!$O$6:$O$1488,$D$3) -> 0 | E9: =SUMIFS('[1]REKAP MUSRENKAB 17 MARET'!$Q$6:$Q$1488,'[1]REKAP MUSRENKAB 17 MARET'!$K$6:$K$1488,B9,'[1]REKAP MUSRENKAB 17 MARET'!$O$6:$O$1488,$E$3) -> 428258332 | F9: =SUMIFS('[1]REKAP MUSRENKAB 17 MARET'!$Q$6:$Q$1488,'[1]REKAP MUSRENKAB 17 MARET'!$K$6:$K$1488,B9,'[1]REKAP MUSRENKAB 17 MARET'!$O$6:$O$1488,$F$3) -> 0 | G9: =SUMIFS('[1]REKAP MUSRENKAB 17 MARET'!$Q$6:$Q$1488,'[1]REKAP MUSRENKAB 17 MARET'!$K$6:$K$1488,B9,'[1]REKAP MUSRENKAB 17 MARET'!$O$6:$O$1488,$G$3) -> 295850000 | H9: =SUMIFS('[1]REKAP MUSRENKAB 17 MARET'!$Q$6:$Q$1488,'[1]REKAP MUSRENKAB 17 MARET'!$K$6:$K$1488,B9,'[1]REKAP MUSRENKAB 17 MARET'!$O$6:$O$1488,$H$3) -> 802500000 | I9: =SUMIFS('[1]REKAP MUSRENKAB 17 MARET'!$Q$6:$Q$1488,'[1]REKAP MUSRENKAB 17 MARET'!$K$6:$K$1488,B9,'[1]REKAP MUSRENKAB 17 MARET'!$O$6:$O$1488,$I$3) -> 48000000 | J9: =SUMIFS('[1]REKAP MUSRENKAB 17 MARET'!$Q$6:$Q$1488,'[1]REKAP MUSRENKAB 17 MARET'!$K$6:$K$1488,B9,'[1]REKAP MUSRENKAB 17 MARET'!$O$6:$O$1488,$J$3) -> 1173930000 | K9: =SUMIFS('[1]REKAP MUSRENKAB 17 MARET'!$Q$6:$Q$1488,'[1]REKAP MUSRENKAB 17 MARET'!$K$6:$K$1488,B9,'[1]REKAP MUSRENKAB 17 MARET'!$O$6:$O$1488,$K$3) -> 125000000 | L9: =SUMIFS('[1]REKAP MUSRENKAB 17 MARET'!$Q$6:$Q$1488,'[1]REKAP MUSRENKAB 17 MARET'!$K$6:$K$1488,B9,'[1]REKAP MUSRENKAB 17 MARET'!$O$6:$O$1488,$L$3) -> 1000000000 | M9: =SUM(C9:L9) -> 3873538332 | N9: 26242470069 | O9: 9478029605 | P9: =N9-O9 -> 16764440464 | Q9: =P9-M9 -> 12890902132
A10: =A9+1 -> 7 | B10: Dinas Perdagangan | C10: =SUMIFS('[1]REKAP MUSRENKAB 17 MARET'!$Q$6:$Q$1488,'[1]REKAP MUSRENKAB 17 MARET'!$K$6:$K$1488,B10,'[1]REKAP MUSRENKAB 17 MARET'!$O$6:$O$1488,$C$3) -> 373800000 | D10: =SUMIFS('[1]REKAP MUSRENKAB 17 MARET'!$Q$6:$Q$1488,'[1]REKAP MUSRENKAB 17 MARET'!$K$6:$K$1488,B10,'[1]REKAP MUSRENKAB 17 MARET'!$O$6:$O$1488,$D$3) -> 164000000 | E10: =SUMIFS('[1]REKAP MUSRENKAB 17 MARET'!$Q$6:$Q$1488,'[1]REKAP MUSRENKAB 17 MARET'!$K$6:$K$1488,B10,'[1]REKAP MUSRENKAB 17 MARET'!$O$6:$O$1488,$E$3) -> 65760000 | F10: =SUMIFS('[1]REKAP MUSRENKAB 17 MARET'!$Q$6:$Q$1488,'[1]REKAP MUSRENKAB 17 MARET'!$K$6:$K$1488,B10,'[1]REKAP MUSRENKAB 17 MARET'!$O$6:$O$1488,$F$3) -> 207035000 | G10: =SUMIFS('[1]REKAP MUSRENKAB 17 MARET'!$Q$6:$Q$1488,'[1]REKAP MUSRENKAB 17 MARET'!$K$6:$K$1488,B10,'[1]REKAP MUSRENKAB 17 MARET'!$O$6:$O$1488,$G$3) -> 63450000 | H10: =SUMIFS('[1]REKAP MUSRENKAB 17 MARET'!$Q$6:$Q$1488,'[1]REKAP MUSRENKAB 17 MARET'!$K$6:$K$1488,B10,'[1]REKAP MUSRENKAB 17 MARET'!$O$6:$O$1488,$H$3) -> 586420000 | I10: =SUMIFS('[1]REKAP MUSRENKAB 17 MARET'!$Q$6:$Q$1488,'[1]REKAP MUSRENKAB 17 MARET'!$K$6:$K$1488,B10,'[1]REKAP MUSRENKAB 17 MARET'!$O$6:$O$1488,$I$3) -> 140760000 | J10: =SUMIFS('[1]REKAP MUSRENKAB 17 MARET'!$Q$6:$Q$1488,'[1]REKAP MUSRENKAB 17 MARET'!$K$6:$K$1488,B10,'[1]REKAP MUSRENKAB 17 MARET'!$O$6:$O$1488,$J$3) -> 444380000 | K10: =SUMIFS('[1]REKAP MUSRENKAB 17 MARET'!$Q$6:$Q$1488,'[1]REKAP MUSRENKAB 17 MARET'!$K$6:$K$1488,B10,'[1]REKAP MUSRENKAB 17 MARET'!$O$6:$O$1488,$K$3) -> 613945000 | L10: =SUMIFS('[1]REKAP MUSRENKAB 17 MARET'!$Q$6:$Q$1488,'[1]REKAP MUSRENKAB 17 MARET'!$K$6:$K$1488,B10,'[1]REKAP MUSRENKAB 17 MARET'!$O$6:$O$1488,$L$3) -> 0 | M10: =SUM(C10:L10) -> 2659550000 | N10: 11446775735 | O10: 6637775735 | P10: =N10-O10 -> 4809000000 | Q10: =P10-M10 -> 2149450000
A11: =A10+1 -> 8 | B11: Dinas Pertanian | C11: =SUMIFS('[1]REKAP MUSRENKAB 17 MARET'!$Q$6:$Q$1488,'[1]REKAP MUSRENKAB 17 MARET'!$K$6:$K$1488,B11,'[1]REKAP MUSRENKAB 17 MARET'!$O$6:$O$1488,$C$3) -> 517503740 | D11: =SUMIFS('[1]REKAP MUSRENKAB 17 MARET'!$Q$6:$Q$1488,'[1]REKAP MUSRENKAB 17 MARET'!$K$6:$K$1488,B11,'[1]REKAP MUSRENKAB 17 MARET'!$O$6:$O$1488,$D$3) -> 1851823000 | E11: =SUMIFS('[1]REKAP MUSRENKAB 17 MARET'!$Q$6:$Q$1488,'[1]REKAP MUSRENKAB 17 MARET'!$K$6:$K$1488,B11,'[1]REKAP MUSRENKAB 17 MARET'!$O$6:$O$1488,$E$3) -> 1805127000 | F11: =SUMIFS('[1]REKAP MUSRENKAB 17 MARET'!$Q$6:$Q$1488,'[1]REKAP MUSRENKAB 17 MARET'!$K$6:$K$1488,B11,'[1]REKAP MUSRENKAB 17 MARET'!$O$6:$O$1488,$F$3) -> 872301000 | G11: =SUMIFS('[1]REKAP MUSRENKAB 17 MARET'!$Q$6:$Q$1488,'[1]REKAP MUSRENKAB 17 MARET'!$K$6:$K$1488,B11,'[1]REKAP MUSRENKAB 17 MARET'!$O$6:$O$1488,$G$3) -> 405000000 | H11: =SUMIFS('[1]REKAP MUSRENKAB 17 MARET'!$Q$6:$Q$1488,'[1]REKAP MUSRENKAB 17 MARET'!$K$6:$K$1488,B11,'[1]REKAP MUSRENKAB 17 MARET'!$O$6:$O$1488,$H$3) -> 2401000000 | I11: =SUMIFS('[1]REKAP MUSRENKAB 17 MARET'!$Q$6:$Q$1488,'[1]REKAP MUSRENKAB 17 MARET'!$K$6:$K$1488,B11,'[1]REKAP MUSRENKAB 17 MARET'!$O$6:$O$1488,$I$3) -> 1347945000 | J11: =SUMIFS('[1]REKAP MUSRENKAB 17 MARET'!$Q$6:$Q$1488,'[1]REKAP MUSRENKAB 17 MARET'!$K$6:$K$1488,B11,'[1]REKAP MUSRENKAB 17 MARET'!$O$6:$O$1488,$J$3) -> 2051075000 | K11: =SUMIFS('[1]REKAP MUSRENKAB 17 MARET'!$Q$6:$Q$1488,'[1]REKAP MUSRENKAB 17 MARET'!$K$6:$K$1488,B11,'[1]REKAP MUSRENKAB 17 MARET'!$O$6:$O$1488,$K$3) -> 2925952589 | L11: =SUMIFS('[1]REKAP MUSRENKAB 17 MARET'!$Q$6:$Q$1488,'[1]REKAP MUSRENKAB 17 MARET'!$K$6:$K$1488,B11,'[1]REKAP MUSRENKAB 17 MARET'!$O$6:$O$1488,$L$3) -> 200000000 | M11: =SUM(C11:L11) -> 14377727329 | N11: 45588869460 | O11: 27365459360 | P11: =N11-O11 -> 18223410100 | Q11: =P11-M11 -> 3845682771
A12: =A11+1 -> 9 | B12: Dinas Pemberdayaan Masyarakat dan Desa | C12: =SUMIFS('[1]REKAP MUSRENKAB 17 MARET'!$Q$6:$Q$1488,'[1]REKAP MUSRENKAB 17 MARET'!$K$6:$K$1488,B12,'[1]REKAP MUSRENKAB 17 MARET'!$O$6:$O$1488,$C$3) -> 0 | D12: =SUMIFS('[1]REKAP MUSRENKAB 17 MARET'!$Q$6:$Q$1488,'[1]REKAP MUSRENKAB 17 MARET'!$K$6:$K$1488,B12,'[1]REKAP MUSRENKAB 17 MARET'!$O$6:$O$1488,$D$3) -> 6475000 | E12: =SUMIFS('[1]REKAP MUSRENKAB 17 MARET'!$Q$6:$Q$1488,'[1]REKAP MUSRENKAB 17 MARET'!$K$6:$K$1488,B12,'[1]REKAP MUSRENKAB 17 MARET'!$O$6:$O$1488,$E$3) -> 5550000 | F12: =SUMIFS('[1]REKAP MUSRENKAB 17 MARET'!$Q$6:$Q$1488,'[1]REKAP MUSRENKAB 17 MARET'!$K$6:$K$1488,B12,'[1]REKAP MUSRENKAB 17 MARET'!$O$6:$O$1488,$F$3) -> 0 | G12: =SUMIFS('[1]REKAP MUSRENKAB 17 MARET'!$Q$6:$Q$1488,'[1]REKAP MUSRENKAB 17 MARET'!$K$6:$K$1488,B12,'[1]REKAP MUSRENKAB 17 MARET'!$O$6:$O$1488,$G$3) -> 0 | H12: =SUMIFS('[1]REKAP MUSRENKAB 17 MARET'!$Q$6:$Q$1488,'[1]REKAP MUSRENKAB 17 MARET'!$K$6:$K$1488,B12,'[1]REKAP MUSRENKAB 17 MARET'!$O$6:$O$1488,$H$3) -> 0 | I12: =SUMIFS('[1]REKAP MUSRENKAB 17 MARET'!$Q$6:$Q$1488,'[1]REKAP MUSRENKAB 17 MARET'!$K$6:$K$1488,B12,'[1]REKAP MUSRENKAB 17 MARET'!$O$6:$O$1488,$I$3) -> 0 | J12: =SUMIFS('[1]REKAP MUSRENKAB 17 MARET'!$Q$6:$Q$1488,'[1]REKAP MUSRENKAB 17 MARET'!$K$6:$K$1488,B12,'[1]REKAP MUSRENKAB 17 MARET'!$O$6:$O$1488,$J$3) -> 0 | K12: =SUMIFS('[1]REKAP MUSRENKAB 17 MARET'!$Q$6:$Q$1488,'[1]REKAP MUSRENKAB 17 MARET'!$K$6:$K$1488,B12,'[1]REKAP MUSRENKAB 17 MARET'!$O$6:$O$1488,$K$3) -> 0 | L12: =SUMIFS('[1]REKAP MUSRENKAB 17 MARET'!$Q$6:$Q$1488,'[1]REKAP MUSRENKAB 17 MARET'!$K$6:$K$1488,B12,'[1]REKAP MUSRENKAB 17 MARET'!$O$6:$O$1488,$L$3) -> 0 | M12: =SUM(C12:L12) -> 12025000 | N12: 45588869460 | O12: 4811596500 | P12: =N12-O12 -> 40777272960 | Q12: =P12-M12 -> 40765247960
A13: =A12+1 -> 10 | B13: Dinas Pendidikan dan Kebudayaan | C13: =SUMIFS('[1]REKAP MUSRENKAB 17 MARET'!$Q$6:$Q$1488,'[1]REKAP MUSRENKAB 17 MARET'!$K$6:$K$1488,B13,'[1]REKAP MUSRENKAB 17 MARET'!$O$6:$O$1488,$C$3) -> 69117500 | D13: =SUMIFS('[1]REKAP MUSRENKAB 17 MARET'!$Q$6:$Q$1488,'[1]REKAP MUSRENKAB 17 MARET'!$K$6:$K$1488,B13,'[1]REKAP MUSRENKAB 17 MARET'!$O$6:$O$1488,$D$3) -> 159125000 | E13: =SUMIFS('[1]REKAP MUSRENKAB 17 MARET'!$Q$6:$Q$1488,'[1]REKAP MUSRENKAB 17 MARET'!$K$6:$K$1488,B13,'[1]REKAP MUSRENKAB 17 MARET'!$O$6:$O$1488,$E$3) -> 1083853800 | F13: =SUMIFS('[1]REKAP MUSRENKAB 17 MARET'!$Q$6:$Q$1488,'[1]REKAP MUSRENKAB 17 MARET'!$K$6:$K$1488,B13,'[1]REKAP MUSRENKAB 17 MARET'!$O$6:$O$1488,$F$3) -> 15000000 | G13: =SUMIFS('[1]REKAP MUSRENKAB 17 MARET'!$Q$6:$Q$1488,'[1]REKAP MUSRENKAB 17 MARET'!$K$6:$K$1488,B13,'[1]REKAP MUSRENKAB 17 MARET'!$O$6:$O$1488,$G$3) -> 310790000 | H13: =SUMIFS('[1]REKAP MUSRENKAB 17 MARET'!$Q$6:$Q$1488,'[1]REKAP MUSRENKAB 17 MARET'!$K$6:$K$1488,B13,'[1]REKAP MUSRENKAB 17 MARET'!$O$6:$O$1488,$H$3) -> 477708000 | I13: =SUMIFS('[1]REKAP MUSRENKAB 17 MARET'!$Q$6:$Q$1488,'[1]REKAP MUSRENKAB 17 MARET'!$K$6:$K$1488,B13,'[1]REKAP MUSRENKAB 17 MARET'!$O$6:$O$1488,$I$3) -> 755018000 | J13: =SUMIFS('[1]REKAP MUSRENKAB 17 MARET'!$Q$6:$Q$1488,'[1]REKAP MUSRENKAB 17 MARET'!$K$6:$K$1488,B13,'[1]REKAP MUSRENKAB 17 MARET'!$O$6:$O$1488,$J$3) -> 690250000 | K13: =SUMIFS('[1]REKAP MUSRENKAB 17 MARET'!$Q$6:$Q$1488,'[1]REKAP MUSRENKAB 17 MARET'!$K$6:$K$1488,B13,'[1]REKAP MUSRENKAB 17 MARET'!$O$6:$O$1488,$K$3) -> 542708000 | L13: =SUMIFS('[1]REKAP MUSRENKAB 17 MARET'!$Q$6:$Q$1488,'[1]REKAP MUSRENKAB 17 MARET'!$K$6:$K$1488,B13,'[1]REKAP MUSRENKAB 17 MARET'!$O$6:$O$1488,$L$3) -> 300000000 | M13: =SUM(C13:L13) -> 4403570300 | N13: 734935497354 | O13: 541576647354 | P13: =N13-O13 -> 193358850000 | Q13: =P13-M13 -> 188955279700
A14: =A13+1 -> 11 | B14: Satuan Polisi Pamong Praja | C14: =SUMIFS('[1]REKAP MUSRENKAB 17 MARET'!$Q$6:$Q$1488,'[1]REKAP MUSRENKAB 17 MARET'!$K$6:$K$1488,B14,'[1]REKAP MUSRENKAB 17 MARET'!$O$6:$O$1488,$C$3) -> 43665000 | D14: =SUMIFS('[1]REKAP MUSRENKAB 17 MARET'!$Q$6:$Q$1488,'[1]REKAP MUSRENKAB 17 MARET'!$K$6:$K$1488,B14,'[1]REKAP MUSRENKAB 17 MARET'!$O$6:$O$1488,$D$3) -> 0 | E14: =SUMIFS('[1]REKAP MUSRENKAB 17 MARET'!$Q$6:$Q$1488,'[1]REKAP MUSRENKAB 17 MARET'!$K$6:$K$1488,B14,'[1]REKAP MUSRENKAB 17 MARET'!$O$6:$O$1488,$E$3) -> 45476000 | F14: =SUMIFS('[1]REKAP MUSRENKAB 17 MARET'!$Q$6:$Q$1488,'[1]REKAP MUSRENKAB 17 MARET'!$K$6:$K$1488,B14,'[1]REKAP MUSRENKAB 17 MARET'!$O$6:$O$1488,$F$3) -> 86297500 | G14: =SUMIFS('[1]REKAP MUSRENKAB 17 MARET'!$Q$6:$Q$1488,'[1]REKAP MUSRENKAB 17 MARET'!$K$6:$K$1488,B14,'[1]REKAP MUSRENKAB 17 MARET'!$O$6:$O$1488,$G$3) -> 172821000 | H14: =SUMIFS('[1]REKAP MUSRENKAB 17 MARET'!$Q$6:$Q$1488,'[1]REKAP MUSRENKAB 17 MARET'!$K$6:$K$1488,B14,'[1]REKAP MUSRENKAB 17 MARET'!$O$6:$O$1488,$H$3) -> 12500000 | I14: =SUMIFS('[1]REKAP MUSRENKAB 17 MARET'!$Q$6:$Q$1488,'[1]REKAP MUSRENKAB 17 MARET'!$K$6:$K$1488,B14,'[1]REKAP MUSRENKAB 17 MARET'!$O$6:$O$1488,$I$3) -> 131791775 | J14: =SUMIFS('[1]REKAP MUSRENKAB 17 MARET'!$Q$6:$Q$1488,'[1]REKAP MUSRENKAB 17 MARET'!$K$6:$K$1488,B14,'[1]REKAP MUSRENKAB 17 MARET'!$O$6:$O$1488,$J$3) -> 18460500 | K14: =SUMIFS('[1]REKAP MUSRENKAB 17 MARET'!$Q$6:$Q$1488,'[1]REKAP MUSRENKAB 17 MARET'!$K$6:$K$1488,B14,'[1]REKAP MUSRENKAB 17 MARET'!$O$6:$O$1488,$K$3) -> 9000000 | L14: =SUMIFS('[1]REKAP MUSRENKAB 17 MARET'!$Q$6:$Q$1488,'[1]REKAP MUSRENKAB 17 MARET'!$K$6:$K$1488,B14,'[1]REKAP MUSRENKAB 17 MARET'!$O$6:$O$1488,$L$3) -> 0 | M14: =SUM(C14:L14) -> 520011775 | N14: 14470754100 | O14: 11984754100 | P14: =N14-O14 -> 2486000000 | Q14: =P14-M14 -> 1965988225
A15: =A14+1 -> 12 | B15: Dinas Sosial, Pemberdayaan Perempuan, dan Perlindungan Anak | C15: =SUMIFS('[1]REKAP MUSRENKAB 17 MARET'!$Q$6:$Q$1488,'[1]REKAP MUSRENKAB 17 MARET'!$K$6:$K$1488,B15,'[1]REKAP MUSRENKAB 17 MARET'!$O$6:$O$1488,$C$3) -> 17460000 | D15: =SUMIFS('[1]REKAP MUSRENKAB 17 MARET'!$Q$6:$Q$1488,'[1]REKAP MUSRENKAB 17 MARET'!$K$6:$K$1488,B15,'[1]REKAP MUSRENKAB 17 MARET'!$O$6:$O$1488,$D$3) -> 119350000 | E15: =SUMIFS('[1]REKAP MUSRENKAB 17 MARET'!$Q$6:$Q$1488,'[1]REKAP MUSRENKAB 17 MARET'!$K$6:$K$1488,B15,'[1]REKAP MUSRENKAB 17 MARET'!$O$6:$O$1488,$E$3) -> 0 | F15: =SUMIFS('[1]REKAP MUSRENKAB 17 MARET'!$Q$6:$Q$1488,'[1]REKAP MUSRENKAB 17 MARET'!$K$6:$K$1488,B15,'[1]REKAP MUSRENKAB 17 MARET'!$O$6:$O$1488,$F$3) -> 0 | G15: =SUMIFS('[1]REKAP MUSRENKAB 17 MARET'!$Q$6:$Q$1488,'[1]REKAP MUSRENKAB 17 MARET'!$K$6:$K$1488,B15,'[1]REKAP MUSRENKAB 17 MARET'!$O$6:$O$1488,$G$3) -> 0 | H15: =SUMIFS('[1]REKAP MUSRENKAB 17 MARET'!$Q$6:$Q$1488,'[1]REKAP MUSRENKAB 17 MARET'!$K$6:$K$1488,B15,'[1]REKAP MUSRENKAB 17 MARET'!$O$6:$O$1488,$H$3) -> 63621000 | I15: =SUMIFS('[1]REKAP MUSRENKAB 17 MARET'!$Q$6:$Q$1488,'[1]REKAP MUSRENKAB 17 MARET'!$K$6:$K$1488,B15,'[1]REKAP MUSRENKAB 17 MARET'!$O$6:$O$1488,$I$3) -> 0 | J15: =SUMIFS('[1]REKAP MUSRENKAB 17 MARET'!$Q$6:$Q$1488,'[1]REKAP MUSRENKAB 17 MARET'!$K$6:$K$1488,B15,'[1]REKAP MUSRENKAB 17 MARET'!$O$6:$O$1488,$J$3) -> 0 | K15: =SUMIFS('[1]REKAP MUSRENKAB 17 MARET'!$Q$6:$Q$1488,'[1]REKAP MUSRENKAB 17 MARET'!$K$6:$K$1488,B15,'[1]REKAP MUSRENKAB 17 MARET'!$O$6:$O$1488,$K$3) -> 0 | L15: =SUMIFS('[1]REKAP MUSRENKAB 17 MARET'!$Q$6:$Q$1488,'[1]REKAP MUSRENKAB 17 MARET'!$K$6:$K$1488,B15,'[1]REKAP MUSRENKAB 17 MARET'!$O$6:$O$1488,$L$3) -> 0 | M15: =SUM(C15:L15) -> 200431000 | N15: 27934068326 | O15: 6849369130 | P15: =N15-O15 -> 21084699196 | Q15: =P15-M15 -> 20884268196
A16: =A15+1 -> 13 | B16: Sekretariat Daerah | C16: =SUMIFS('[1]REKAP MUSRENKAB 17 MARET'!$Q$6:$Q$1488,'[1]REKAP MUSRENKAB 17 MARET'!$K$6:$K$1488,B16,'[1]REKAP MUSRENKAB 17 MARET'!$O$6:$O$1488,$C$3) -> 0 | D16: =SUMIFS('[1]REKAP MUSRENKAB 17 MARET'!$Q$6:$Q$1488,'[1]REKAP MUSRENKAB 17 MARET'!$K$6:$K$1488,B16,'[1]REKAP MUSRENKAB 17 MARET'!$O$6:$O$1488,$D$3) -> 25000000 | E16: =SUMIFS('[1]REKAP MUSRENKAB 17 MARET'!$Q$6:$Q$1488,'[1]REKAP MUSRENKAB 17 MARET'!$K$6:$K$1488,B16,'[1]REKAP MUSRENKAB 17 MARET'!$O$6:$O$1488,$E$3) -> 435000000 | F16: =SUMIFS('[1]REKAP MUSRENKAB 17 MARET'!$Q$6:$Q$1488,'[1]REKAP MUSRENKAB 17 MARET'!$K$6:$K$1488,B16,'[1]REKAP MUSRENKAB 17 MARET'!$O$6:$O$1488,$F$3) -> 150000000 | G16: =SUMIFS('[1]REKAP MUSRENKAB 17 MARET'!$Q$6:$Q$1488,'[1]REKAP MUSRENKAB 17 MARET'!$K$6:$K$1488,B16,'[1]REKAP MUSRENKAB 17 MARET'!$O$6:$O$1488,$G$3) -> 75600000 | H16: =SUMIFS('[1]REKAP MUSRENKAB 17 MARET'!$Q$6:$Q$1488,'[1]REKAP MUSRENKAB 17 MARET'!$K$6:$K$1488,B16,'[1]REKAP MUSRENKAB 17 MARET'!$O$6:$O$1488,$H$3) -> 375000000 | I16: =SUMIFS('[1]REKAP MUSRENKAB 17 MARET'!$Q$6:$Q$1488,'[1]REKAP MUSRENKAB 17 MARET'!$K$6:$K$1488,B16,'[1]REKAP MUSRENKAB 17 MARET'!$O$6:$O$1488,$I$3) -> 55000000 | J16: =SUMIFS('[1]REKAP MUSRENKAB 17 MARET'!$Q$6:$Q$1488,'[1]REKAP MUSRENKAB 17 MARET'!$K$6:$K$1488,B16,'[1]REKAP MUSRENKAB 17 MARET'!$O$6:$O$1488,$J$3) -> 0 | K16: =SUMIFS('[1]REKAP MUSRENKAB 17 MARET'!$Q$6:$Q$1488,'[1]REKAP MUSRENKAB 17 MARET'!$K$6:$K$1488,B16,'[1]REKAP MUSRENKAB 17 MARET'!$O$6:$O$1488,$K$3) -> 38000000 | L16: =SUMIFS('[1]REKAP MUSRENKAB 17 MARET'!$Q$6:$Q$1488,'[1]REKAP MUSRENKAB 17 MARET'!$K$6:$K$1488,B16,'[1]REKAP MUSRENKAB 17 MARET'!$O$6:$O$1488,$L$3) -> 0 | M16: =SUM(C16:L16) -> 1153600000 | N16: 37722344000 | O16: 28439731000 | P16: =N16-O16 -> 9282613000 | Q16: =P16-M16 -> 8129013000
A17: =A16+1 -> 14 | B17: Badan Penanggulangan Bencana Daerah | C17: =SUMIFS('[1]REKAP MUSRENKAB 17 MARET'!$Q$6:$Q$1488,'[1]REKAP MUSRENKAB 17 MARET'!$K$6:$K$1488,B17,'[1]REKAP MUSRENKAB 17 MARET'!$O$6:$O$1488,$C$3) -> 0 | D17: =SUMIFS('[1]REKAP MUSRENKAB 17 MARET'!$Q$6:$Q$1488,'[1]REKAP MUSRENKAB 17 MARET'!$K$6:$K$1488,B17,'[1]REKAP MUSRENKAB 17 MARET'!$O$6:$O$1488,$D$3) -> 0 | E17: =SUMIFS('[1]REKAP MUSRENKAB 17 MARET'!$Q$6:$Q$1488,'[1]REKAP MUSRENKAB 17 MARET'!$K$6:$K$1488,B17,'[1]REKAP MUSRENKAB 17 MARET'!$O$6:$O$1488,$E$3) -> 0 | F17: =SUMIFS('[1]REKAP MUSRENKAB 17 MARET'!$Q$6:$Q$1488,'[1]REKAP MUSRENKAB 17 MARET'!$K$6:$K$1488,B17,'[1]REKAP MUSRENKAB 17 MARET'!$O$6:$O$1488,$F$3) -> 0 | G17: =SUMIFS('[1]REKAP MUSRENKAB 17 MARET'!$Q$6:$Q$1488,'[1]REKAP MUSRENKAB 17 MARET'!$K$6:$K$1488,B17,'[1]REKAP MUSRENKAB 17 MARET'!$O$6:$O$1488,$G$3) -> 125000000 | H17: =SUMIFS('[1]REKAP MUSRENKAB 17 MARET'!$Q$6:$Q$1488,'[1]REKAP MUSRENKAB 17 MARET'!$K$6:$K$1488,B17,'[1]REKAP MUSRENKAB 17 MARET'!$O$6:$O$1488,$H$3) -> 60000000 | I17: =SUMIFS('[1]REKAP MUSRENKAB 17 MARET'!$Q$6:$Q$1488,'[1]REKAP MUSRENKAB 17 MARET'!$K$6:$K$1488,B17,'[1]REKAP MUSRENKAB 17 MARET'!$O$6:$O$1488,$I$3) -> 101333000 | J17: =SUMIFS('[1]REKAP MUSRENKAB 17 MARET'!$Q$6:$Q$1488,'[1]REKAP MUSRENKAB 17 MARET'!$K$6:$K$1488,B17,'[1]REKAP MUSRENKAB 17 MARET'!$O$6:$O$1488,$J$3) -> 0 | K17: =SUMIFS('[1]REKAP MUSRENKAB 17 MARET'!$Q$6:$Q$1488,'[1]REKAP MUSRENKAB 17 MARET'!$K$6:$K$1488,B17,'[1]REKAP MUSRENKAB 17 MARET'!$O$6:$O$1488,$K$3) -> 665000000 | L17: =SUMIFS('[1]REKAP MUSRENKAB 17 MARET'!$Q$6:$Q$1488,'[1]REKAP MUSRENKAB 17 MARET'!$K$6:$K$1488,B17,'[1]REKAP MUSRENKAB 17 MARET'!$O$6:$O$1488,$L$3) -> 840000000 | M17: =SUM(C17:L17) -> 1791333000 | N17: 6639465427 | O17: 3882965427 | P17: =N17-O17 -> 2756500000 | Q17: =P17-M17 -> 965167000
... A20: =A19+1 -> 17 | B20: Dinas Pekerjaan Umum, Penataan Ruang, Perumahan dan Kawasan Permukiman | C20: =SUMIFS('[1]REKAP MUSRENKAB 17 MARET'!$Q$6:$Q$1488,'[1]REKAP MUSRENKAB 17 MARET'!$K$6:$K$1488,B20,'[1]REKAP MUSRENKAB 17 MARET'!$O$6:$O$1488,$C$3) -> 8484744000 | D20: =SUMIFS('[1]REKAP MUSRENKAB 17 MARET'!$Q$6:$Q$1488,'[1]REKAP MUSRENKAB 17 MARET'!$K$6:$K$1488,B20,'[1]REKAP MUSRENKAB 17 MARET'!$O$6:$O$1488,$D$3) -> 10424598760 | E20: =SUMIFS('[1]REKAP MUSRENKAB 17 MARET'!$Q$6:$Q$1488,'[1]REKAP MUSRENKAB 17 MARET'!$K$6:$K$1488,B20,'[1]REKAP MUSRENKAB 17 MARET'!$O$6:$O$1488,$E$3) -> 1.1369749e+10 | F20: =SUMIFS('[1]REKAP MUSRENKAB 17 MARET'!$Q$6:$Q$1488,'[1]REKAP MUSRENKAB 17 MARET'!$K$6:$K$1488,B20,'[1]REKAP MUSRENKAB 17 MARET'!$O$6:$O$1488,$F$3) -> 7832204016 | G20: =SUMIFS('[1]REKAP MUSRENKAB 17 MARET'!$Q$6:$Q$1488,'[1]REKAP MUSRENKAB 17 MARET'!$K$6:$K$1488,B20,'[1]REKAP MUSRENKAB 17 MARET'!$O$6:$O$1488,$G$3) -> 4154978000 | H20: =SUMIFS('[1]REKAP MUSRENKAB 17 MARET'!$Q$6:$Q$1488,'[1]REKAP MUSRENKAB 17 MARET'!$K$6:$K$1488,B20,'[1]REKAP MUSRENKAB 17 MARET'!$O$6:$O$1488,$H$3) -> 6299569760 | I20: =SUMIFS('[1]REKAP MUSRENKAB 17 MARET'!$Q$6:$Q$1488,'[1]REKAP MUSRENKAB 17 MARET'!$K$6:$K$1488,B20,'[1]REKAP MUSRENKAB 17 MARET'!$O$6:$O$1488,$I$3) -> 7.3171272e+09 | J20: =SUMIFS('[1]REKAP MUSRENKAB 17 MARET'!$Q$6:$Q$1488,'[1]REKAP MUSRENKAB 17 MARET'!$K$6:$K$1488,B20,'[1]REKAP MUSRENKAB 17 MARET'!$O$6:$O$1488,$J$3) -> 10892535195 | K20: =SUMIFS('[1]REKAP MUSRENKAB 17 MARET'!$Q$6:$Q$1488,'[1]REKAP MUSRENKAB 17 MARET'!$K$6:$K$1488,B20,'[1]REKAP MUSRENKAB 17 MARET'!$O$6:$O$1488,$K$3) -> 1.5614671e+10 | L20: =SUMIFS('[1]REKAP MUSRENKAB 17 MARET'!$Q$6:$Q$1488,'[1]REKAP MUSRENKAB 17 MARET'!$K$6:$K$1488,B20,'[1]REKAP MUSRENKAB 17 MARET'!$O$6:$O$1488,$L$3) -> 13519076000 | M20: =SUM(C20:L20) -> 9.5909253e+10 | N20: 178105229000 | O20: 24205526000 | P20: =N20-O20 -> 153899703000 | Q20: =P20-M20 -> 5.799045e+10
B21: JUMLAH | C21: =SUM(C4:C20) -> 10044640240 | D21: =SUM(D4:D20) -> 14622866760 | E21: =SUM(E4:E20) -> 1.6864425e+10 | F21: =SUM(F4:F20) -> 10188837516 | G21: =SUM(G4:G20) -> 6300000000 | H21: =SUM(H4:H20) -> 13556358760 | I21: =SUM(I4:I20) -> 1.0875273e+10 | J21: =SUM(J4:J20) -> 16269130695 | ... L21: =SUM(L4:L20) -> 16782776000 | M21: =SUM(C21:L21) -> 1.3680641e+11
M23: 1.3682584e+11
M24: =M23-M21 -> 19425000

Sheet PAGU PER PRIORITAS
A1: PEMETAAN HASIL FORUM PERANGKAT DAERAH TERHADAP PRIORITAS DAERAH TAHUN 2027
A3: NO | B3: URAIAN PRIORITAS | C3: PAGU (Rp) | D3: PERSENTASE
A4: PKAB 1 | B4: Sejahtera dari Desa | C4: =SUMIF('[1]REKAP MUSRENKAB 17 MARET'!$B$6:$B$1488,B4,'[1]REKAP MUSRENKAB 17 MARET'!$Q$6:$Q$1488) -> 12025000 | D4: =C4/$C$13*100 -> 0.0087885447
A5: PKAB 2 | B5: Pembangunan SDM Unggul dan Berdaya Saing | C5: =SUMIF('[1]REKAP MUSRENKAB 17 MARET'!$B$6:$B$1488,B5,'[1]REKAP MUSRENKAB 17 MARET'!$Q$6:$Q$1488) -> 5370470300 | D5: =C5/$C$13*100 -> 3.925041
A6: PKAB 3 | B6: Pengentasan Pengangguran | C6: =SUMIF('[1]REKAP MUSRENKAB 17 MARET'!$B$6:$B$1488,B6,'[1]REKAP MUSRENKAB 17 MARET'!$Q$6:$Q$1488) -> 280000000 | D6: =C6/$C$13*100 -> 0.20463971
A7: PKAB 4 | B7: Transformasi dan Kemandirian Ekonomi | C7: =SUMIF('[1]REKAP MUSRENKAB 17 MARET'!$B$6:$B$1488,B7,'[1]REKAP MUSRENKAB 17 MARET'!$Q$6:$Q$1488) -> 8891119332 | D7: =C7/$C$13*100 -> 6.4981289
A8: PKAB 5 | B8: Ketahanan Sosial | C8: =SUMIF('[1]REKAP MUSRENKAB 17 MARET'!$B$6:$B$1488,B8,'[1]REKAP MUSRENKAB 17 MARET'!$Q$6:$Q$1488) -> 210431000 | D8: =C8/$C$13*100 -> 0.15379478
A9: PKAB 6 | B9: Agrominapolitan | C9: =SUMIF('[1]REKAP MUSRENKAB 17 MARET'!$B$6:$B$1488,B9,'[1]REKAP MUSRENKAB 17 MARET'!$Q$6:$Q$1488) -> 14880727329 | D9: =C9/$C$13*100 -> 10.87567
A10: PKAB 7 | B10: Infrastruktur Berkelanjutan | C10: =SUMIF('[1]REKAP MUSRENKAB 17 MARET'!$B$6:$B$1488,B10,'[1]REKAP MUSRENKAB 17 MARET'!$Q$6:$Q$1488) -> 1.0509803e+11 | D10: =C10/$C$13*100 -> 76.811536
A11: PKAB 8 | B11: Transformasi Tata Kelola | C11: =SUMIF('[1]REKAP MUSRENKAB 17 MARET'!$B$6:$B$1488,B11,'[1]REKAP MUSRENKAB 17 MARET'!$Q$6:$Q$1488) -> 1683036775 | D11: =C11/$C$13*100 -> 1.2300577
A12: PKAB 9 | B12: Harmoni Sosial | C12: =SUMIF('[1]REKAP MUSRENKAB 17 MARET'!$B$6:$B$1488,B12,'[1]REKAP MUSRENKAB 17 MARET'!$Q$6:$Q$1488) -> 400000000 | D12: =C12/$C$13*100 -> 0.29234244
B13: JUMLAH | C13: =SUM(C4:C12) -> 1.3682584e+11 | D13: =C13/$C$13*100 -> 100
B15: CEK | C15: 1.3682584e+11
C16: =C15-C13 -> 0

Sheet PAGU PER PROGRAM
A1: PERBANDINGAN JUMLAH USULAN DESA PER PROGRAM DENGAN PAGU PROGRAM RANWAL RENJA OPD TAHUN 2027
A3: NO | B3: PERANGKAT DAERAH | C3: PROGRAM | D3: PAGU USULAN DESA (Rp) | E3: PAGU TERSEDIA DI OPD (Rp) | F3: SELISIH | G3: KETERANGAN
A4: 1 | B4: Badan Kesatuan Bangsa dan Politik | C4: PROGRAM PEMBINAAN DAN PENGEMBANGAN KETAHANAN EKONOMI, SOSIAL, DAN BUDAYA | D4: =SUMIFS('[1]REKAP MUSRENKAB 17 MARET'!$Q$6:$Q$1488,'[1]REKAP MUSRENKAB 17 MARET'!$K$6:$K$1488,B4,'[1]REKAP MUSRENKAB 17 MARET'!$D$6:$D$1488,C4) -> 19425000 | E4: 237000000 | F4: =E4-D4 -> 217575000 | G4: Sosial dan Kelembagaan (Kapasitas Pemdes, Karang taruna, Perlindungan Sosial Komunitas)
A5: =A4+1 -> 2 | B5: Badan Penanggulangan Bencana Daerah | C5: PROGRAM PENANGGULANGAN BENCANA | D5: =SUMIFS('[1]REKAP MUSRENKAB 17 MARET'!$Q$6:$Q$1488,'[1]REKAP MUSRENKAB 17 MARET'!$K$6:$K$1488,B5,'[1]REKAP MUSRENKAB 17 MARET'!$D$6:$D$1488,C5) -> 1791333000 | E5: 2756500000 | F5: =E5-D5 -> 965167000 | G5: Sosial dan Kelembagaan (Kapasitas Pemdes, Karang taruna, Perlindungan Sosial Komunitas)
A6: =A5+1 -> 3 | B6: Dinas Kelautan, Perikanan, dan Ketahanan Pangan | C6: PROGRAM Pengelolaan Perikanan Tangkap | D6: =SUMIFS('[1]REKAP MUSRENKAB 17 MARET'!$Q$6:$Q$1488,'[1]REKAP MUSRENKAB 17 MARET'!$K$6:$K$1488,B6,'[1]REKAP MUSRENKAB 17 MARET'!$D$6:$D$1488,C6) -> 180000000 | E6: 2720000000 | F6: =E6-D6 -> 2540000000 | G6: Penguatan Ekonomi Desa (BUMDes, Alat Produksi UMKM, Desa Wisata, Dukungan Pertanian/Perikanan)
A7: =A6+1 -> 4 | B7: Dinas Kelautan, Perikanan, dan Ketahanan Pangan | C7: PROGRAM PENINGKATAN DIVERSIFIKASI DAN KETAHANAN PANGAN MASYARAKAT | D7: =SUMIFS('[1]REKAP MUSRENKAB 17 MARET'!$Q$6:$Q$1488,'[1]REKAP MUSRENKAB 17 MARET'!$K$6:$K$1488,B7,'[1]REKAP MUSRENKAB 17 MARET'!$D$6:$D$1488,C7) -> 238000000 | E7: 1042632802 | F7: =E7-D7 -> 804632802 | G7: Penguatan Ekonomi Desa (BUMDes, Alat Produksi UMKM, Desa Wisata, Dukungan Pertanian/Perikanan)
A8: =A7+1 -> 5 | B8: Dinas Kelautan, Perikanan, dan Ketahanan Pangan | C8: PROGRAM Pengelolaan Perikanan Budidaya | D8: =SUMIFS('[1]REKAP MUSRENKAB 17 MARET'!$Q$6:$Q$1488,'[1]REKAP MUSRENKAB 17 MARET'!$K$6:$K$1488,B8,'[1]REKAP MUSRENKAB 17 MARET'!$D$6:$D$1488,C8) -> 0 | E8: 4383000000 | F8: =E8-D8 -> 4383000000 | G8: Penguatan Ekonomi Desa (BUMDes, Alat Produksi UMKM, Desa Wisata, Dukungan Pertanian/Perikanan)
A9: =A8+1 -> 6 | B9: Dinas Kelautan, Perikanan, dan Ketahanan Pangan | C9: PROGRAM Pengolahan dan Pemasaran Hasil Perikanan | D9: =SUMIFS('[1]REKAP MUSRENKAB 17 MARET'!$Q$6:$Q$1488,'[1]REKAP MUSRENKAB 17 MARET'!$K$6:$K$1488,B9,'[1]REKAP MUSRENKAB 17 MARET'!$D$6:$D$1488,C9) -> 125000000 | E9: 2171400000 | F9: =E9-D9 -> 2046400000 | G9: Penguatan Ekonomi Desa (BUMDes, Alat Produksi UMKM, Desa Wisata, Dukungan Pertanian/Perikanan)
A10: =A9+1 -> 7 | B10: Dinas Kesehatan, Pengendalian Penduduk dan Keluarga Berencana | C10: PROGRAM PEMENUHAN UPAYA KESEHATAN PERORANGAN DAN UPAYA KESEHATAN MASYARAKAT | D10: =SUMIFS('[1]REKAP MUSRENKAB 17 MARET'!$Q$6:$Q$1488,'[1]REKAP MUSRENKAB 17 MARET'!$K$6:$K$1488,B10,'[1]REKAP MUSRENKAB 17 MARET'!$D$6:$D$1488,C10) -> 778670000 | E10: 211172684496 | F10: =E10-D10 -> 210394014496 | G10: Peningkatan Kualitas SDM (Intervensi Stunting, Posyandu, Beasiswa, Pelatihan Keterampilan Kerja)
A11: =A10+1 -> 8 | B11: Dinas Lingkungan Hidup | C11: PROGRAM PENGENDALIAN PENCEMARAN DAN/ATAU KERUSAKAN LINGKUNGAN HIDUP. | D11: =SUMIFS('[1]REKAP MUSRENKAB 17 MARET'!$Q$6:$Q$1488,'[1]REKAP MUSRENKAB 17 MARET'!$K$6:$K$1488,B11,'[1]REKAP MUSRENKAB 17 MARET'!$D$6:$D$1488,C11) -> 125000000 | E11: 474000000 | F11: =E11-D11 -> 349000000 | G11: Sosial dan Kelembagaan (Kapasitas Pemdes, Karang taruna, Perlindungan Sosial Komunitas)
A12: =A11+1 -> 9 | B12: Dinas Lingkungan Hidup | C12: PROGRAM PENGELOLAAN PERSAMPAHAN | D12: =SUMIFS('[1]REKAP MUSRENKAB 17 MARET'!$Q$6:$Q$1488,'[1]REKAP MUSRENKAB 17 MARET'!$K$6:$K$1488,B12,'[1]REKAP MUSRENKAB 17 MARET'!$D$6:$D$1488,C12) -> 4459897600 | E12: 16349637430 | F12: =E12-D12 -> 11889739830 | G12: Sosial dan Kelembagaan (Kapasitas Pemdes, Karang taruna, Perlindungan Sosial Komunitas)
A13: =A12+1 -> 10 | B13: Dinas Pariwisata, Ekonomi Kreatif, Pemuda, dan Olahraga | C13: PROGRAM Pengembangan kapasitas daya saing kepemudaan | D13: =SUMIFS('[1]REKAP MUSRENKAB 17 MARET'!$Q$6:$Q$1488,'[1]REKAP MUSRENKAB 17 MARET'!$K$6:$K$1488,B13,'[1]REKAP MUSRENKAB 17 MARET'!$D$6:$D$1488,C13) -> 0 | E13: 5211314464 | F13: =E13-D13 -> 5211314464 | G13: Penguatan Ekonomi Desa (BUMDes, Alat Produksi UMKM, Desa Wisata, Dukungan Pertanian/Perikanan)
A14: =A13+1 -> 11 | B14: Dinas Pariwisata, Ekonomi Kreatif, Pemuda, dan Olahraga | C14: PROGRAM PENGEMBANGAN SUMBER DAYA PARIWISATA DAN EKONOMI KREATIF | D14: =SUMIFS('[1]REKAP MUSRENKAB 17 MARET'!$Q$6:$Q$1488,'[1]REKAP MUSRENKAB 17 MARET'!$K$6:$K$1488,B14,'[1]REKAP MUSRENKAB 17 MARET'!$D$6:$D$1488,C14) -> 50000000 | E14: 1120140000 | F14: =E14-D14 -> 1070140000 | G14: Penguatan Ekonomi Desa (BUMDes, Alat Produksi UMKM, Desa Wisata, Dukungan Pertanian/Perikanan)
A15: =A14+1 -> 12 | B15: Dinas Pariwisata, Ekonomi Kreatif, Pemuda, dan Olahraga | C15: Program Pengembangan Kapasitas Daya Saing Keolahragaan | D15: =SUMIFS('[1]REKAP MUSRENKAB 17 MARET'!$Q$6:$Q$1488,'[1]REKAP MUSRENKAB 17 MARET'!$K$6:$K$1488,B15,'[1]REKAP MUSRENKAB 17 MARET'!$D$6:$D$1488,C15) -> 965280000 | E15: 5277082500 | F15: =E15-D15 -> 4311802500 | G15: Penguatan Ekonomi Desa (BUMDes, Alat Produksi UMKM, Desa Wisata, Dukungan Pertanian/Perikanan)
A16: =A15+1 -> 13 | B16: Dinas Pariwisata, Ekonomi Kreatif, Pemuda, dan Olahraga | C16: PROGRAM PENINGKATAN DAYA TARIK DESTINASI PARIWISATA | D16: =SUMIFS('[1]REKAP MUSRENKAB 17 MARET'!$Q$6:$Q$1488,'[1]REKAP MUSRENKAB 17 MARET'!$K$6:$K$1488,B16,'[1]REKAP MUSRENKAB 17 MARET'!$D$6:$D$1488,C16) -> 2858258332 | E16: 1066000000 | F16: =E16-D16 -> -1792258332 | G16: Penguatan Ekonomi Desa (BUMDes, Alat Produksi UMKM, Desa Wisata, Dukungan Pertanian/Perikanan)
... A37: =A36+1 -> 34 | B37: Dinas Pekerjaan Umum, Penataan Ruang, Perumahan dan Kawasan Permukiman | C37: PROGRAM PENGEMBANGAN SISTEM DAN PENGELOLAAN PERSAMPAHAN REGIONAL | D37: =SUMIFS('[1]REKAP MUSRENKAB 17 MARET'!$Q$6:$Q$1488,'[1]REKAP MUSRENKAB 17 MARET'!$K$6:$K$1488,B37,'[1]REKAP MUSRENKAB 17 MARET'!$D$6:$D$1488,C37) -> 0 | E37: 1000000000 | F37: =E37-D37 -> 1000000000 | G37: Infrastruktur Dasar (Jalan lingkungan, Irigasi kecil, Air Bersih, Sanitasi/Rutilahu)
D38: =SUM(D4:D37) -> 1.3682584e+11 | E38: =SUM(E4:E37) -> 615061498792 | F38: =E38-D38 -> 4.7823566e+11
C40: CEK | D40: 1.3682584e+11
C41: SELISIH | D41: =D40-D38 -> 0
C43: SUB TOTAL | D43: =SUBTOTAL(9,D4:D37) -> 1.3682584e+11

Sheet REKAP PER OPD SAJA
A1: REKAP PER OPD_KECAMATAN USULAN DESA TAHUN 2027 (FORUM PERANGKAT DAERAH)
A2: Rekap Tanggal 3 April 2026
A3: NO | B3: OPD TUJUAN | C3: JUMLAH | D3: PILAR | E3: PAGU TOTAL OPD | F3: PROGRAM PENUNJANG | G3: PAGU CORE BISNIS | H3: SELISIH PAGU COR BISNIS DGN USULAN DESA
A4: 1 | B4: Badan Kesatuan Bangsa dan Politik | C4: =SUMIF('REKAP 3 APRIL (edit)'!$K$6:$K$1452,B4,'REKAP 3 APRIL (edit)'!$O$6:$O$1452) -> 19425000 | D4: Sosial dan Kelembagaan (Kapasitas Pemdes, Karang taruna, Perlindungan Sosial Komunitas) | E4: 8867508178 | F4: 4442008178 | G4: =E4-F4 -> 4425500000 | H4: =G4-C4 -> 4406075000
A5: =A4+1 -> 2 | B5: Dinas Kearsipan dan Perpustakaan | C5: =SUMIF('REKAP 3 APRIL (edit)'!$K$6:$K$1452,B5,'REKAP 3 APRIL (edit)'!$O$6:$O$1452) -> 0 | D5: Peningkatan Kualitas SDM (Intervensi Stunting, Posyandu, Beasiswa, Pelatihan Keterampilan Kerja) | G5: =E5-F5 -> 0 | H5: =G5-C5 -> 0
A6: =A5+1 -> 3 | B6: Dinas Kesehatan, Pengendalian Penduduk dan Keluarga Berencana | C6: =SUMIF('REKAP 3 APRIL (edit)'!$K$6:$K$1452,B6,'REKAP 3 APRIL (edit)'!$O$6:$O$1452) -> 1258670000 | D6: Peningkatan Kualitas SDM (Intervensi Stunting, Posyandu, Beasiswa, Pelatihan Keterampilan Kerja) | E6: 699757253403 | F6: 324873540000 | G6: =E6-F6 -> 374883713403 | H6: =G6-C6 -> 373625043403
A7: =A6+1 -> 4 | B7: Dinas Kelautan, Perikanan, dan Ketahanan Pangan | C7: =SUMIF('REKAP 3 APRIL (edit)'!$K$6:$K$1452,B7,'REKAP 3 APRIL (edit)'!$O$6:$O$1452) -> 562540000 | D7: Penguatan Ekonomi Desa (BUMDes, Alat Produksi UMKM, Desa Wisata, Dukungan Pertanian/Perikanan) | E7: 21091507877 | F7: 9331186759 | G7: =E7-F7 -> 11760321118 | H7: =G7-C7 -> 11197781118
A8: =A7+1 -> 5 | B8: Dinas Perindustrian, Koperasi, Usaha Kecil dan Menengah, dan Tenaga Kerja | C8: =SUMIF('REKAP 3 APRIL (edit)'!$K$6:$K$1452,B8,'REKAP 3 APRIL (edit)'!$O$6:$O$1452) -> 3410761000 | D8: Penguatan Ekonomi Desa (BUMDes, Alat Produksi UMKM, Desa Wisata, Dukungan Pertanian/Perikanan) | E8: 25392059315 | F8: 10542461515 | G8: =E8-F8 -> 14849597800 | H8: =G8-C8 -> 11438836800
A9: =A8+1 -> 6 | B9: Dinas Pariwisata, Ekonomi Kreatif, Pemuda, dan Olahraga | C9: =SUMIF('REKAP 3 APRIL (edit)'!$K$6:$K$1452,B9,'REKAP 3 APRIL (edit)'!$O$6:$O$1452) -> 3873538332 | D9: Penguatan Ekonomi Desa (BUMDes, Alat Produksi UMKM, Desa Wisata, Dukungan Pertanian/Perikanan) | E9: 26242470069 | F9: 9478029605 | G9: =E9-F9 -> 16764440464 | H9: =G9-C9 -> 12890902132
A10: =A9+1 -> 7 | B10: Dinas Perdagangan | C10: =SUMIF('REKAP 3 APRIL (edit)'!$K$6:$K$1452,B10,'REKAP 3 APRIL (edit)'!$O$6:$O$1452) -> 2773523783 | D10: Penguatan Ekonomi Desa (BUMDes, Alat Produksi UMKM, Desa Wisata, Dukungan Pertanian/Perikanan) | E10: 11446775735 | F10: 6637775735 | G10: =E10-F10 -> 4809000000 | H10: =G10-C10 -> 2035476217
A11: =A10+1 -> 8 | B11: Dinas Pertanian | C11: =SUMIF('REKAP 3 APRIL (edit)'!$K$6:$K$1452,B11,'REKAP 3 APRIL (edit)'!$O$6:$O$1452) -> 14128210199 | D11: Penguatan Ekonomi Desa (BUMDes, Alat Produksi UMKM, Desa Wisata, Dukungan Pertanian/Perikanan) | E11: 45588869460 | F11: 27365459360 | G11: =E11-F11 -> 18223410100 | H11: =G11-C11 -> 4095199901
A12: =A11+1 -> 9 | B12: Dinas Pemberdayaan Masyarakat dan Desa | C12: =SUMIF('REKAP 3 APRIL (edit)'!$K$6:$K$1452,B12,'REKAP 3 APRIL (edit)'!$O$6:$O$1452) -> 12025000 | D12: Sosial dan Kelembagaan (Kapasitas Pemdes, Karang taruna, Perlindungan Sosial Komunitas) | E12: 45588869460 | F12: 4811596500 | G12: =E12-F12 -> 40777272960 | H12: =G12-C12 -> 40765247960
A13: =A12+1 -> 10 | B13: Dinas Pendidikan dan Kebudayaan | C13: =SUMIF('REKAP 3 APRIL (edit)'!$K$6:$K$1452,B13,'REKAP 3 APRIL (edit)'!$O$6:$O$1452) -> 5493077800 | D13: Peningkatan Kualitas SDM (Intervensi Stunting, Posyandu, Beasiswa, Pelatihan Keterampilan Kerja) | E13: 734935497354 | F13: 541576647354 | G13: =E13-F13 -> 193358850000 | H13: =G13-C13 -> 187865772200
A14: =A13+1 -> 11 | B14: Satuan Polisi Pamong Praja | C14: =SUMIF('REKAP 3 APRIL (edit)'!$K$6:$K$1452,B14,'REKAP 3 APRIL (edit)'!$O$6:$O$1452) -> 520011775 | D14: Sosial dan Kelembagaan (Kapasitas Pemdes, Karang taruna, Perlindungan Sosial Komunitas) | E14: 14470754100 | F14: 11984754100 | G14: =E14-F14 -> 2486000000 | H14: =G14-C14 -> 1965988225
A15: =A14+1 -> 12 | B15: Dinas Sosial, Pemberdayaan Perempuan, dan Perlindungan Anak | C15: =SUMIF('REKAP 3 APRIL (edit)'!$K$6:$K$1452,B15,'REKAP 3 APRIL (edit)'!$O$6:$O$1452) -> 90431000 | D15: Sosial dan Kelembagaan (Kapasitas Pemdes, Karang taruna, Perlindungan Sosial Komunitas) | E15: 27934068326 | F15: 6849369130 | G15: =E15-F15 -> 21084699196 | H15: =G15-C15 -> 20994268196
A16: =A15+1 -> 13 | B16: Sekretariat Daerah | C16: =SUMIF('REKAP 3 APRIL (edit)'!$K$6:$K$1452,B16,'REKAP 3 APRIL (edit)'!$O$6:$O$1452) -> 1235513878 | D16: Sosial dan Kelembagaan (Kapasitas Pemdes, Karang taruna, Perlindungan Sosial Komunitas) | E16: 37722344000 | F16: 28439731000 | G16: =E16-F16 -> 9282613000 | H16: =G16-C16 -> 8047099122
A17: =A16+1 -> 14 | B17: Badan Penanggulangan Bencana Daerah | C17: =SUMIF('REKAP 3 APRIL (edit)'!$K$6:$K$1452,B17,'REKAP 3 APRIL (edit)'!$O$6:$O$1452) -> 1775000000 | D17: Sosial dan Kelembagaan (Kapasitas Pemdes, Karang taruna, Perlindungan Sosial Komunitas) | E17: 6639465427 | F17: 3882965427 | G17: =E17-F17 -> 2756500000 | H17: =G17-C17 -> 981500000
... A20: =A19+1 -> 17 | B20: Dinas Pekerjaan Umum, Penataan Ruang, Perumahan dan Kawasan Permukiman | C20: =SUMIF('REKAP 3 APRIL (edit)'!$K$6:$K$1452,B20,'REKAP 3 APRIL (edit)'!$O$6:$O$1452) -> 9.3831266e+10 | D20: Infrastruktur Dasar (Jalan lingkungan, Irigasi kecil, talud, dll) | E20: 178105229000 | F20: 24205526000 | G20: =E20-F20 -> 153899703000 | H20: =G20-C20 -> 6.0068437e+10
B21: JUMLAH | C21: =SUM(C4:C20) -> 1.3750584e+11
C23: 1.3750584e+11
C24: =C23-C21 -> 0
B26: Catatan PU yang mendukung stunting :
B27: - Air Bersih
B28: Jaringan Air Bersih SPAM ( Mesin Air dan Instalasi Perpipaan Ke Rumah ) | C28: 150000000
B29: Pembangunan Baru Spam Jaringan Perpipaan (Perpipaan Air Bersih Kpspam) | C29: 100000000
B30: Sumur Bor | C30: 210000000
B31: Perpipaan Air Bersih | C31: 150000000

Sheet REKAP 3 APRIL (edit)
A3: NO | B3: PRIORITAS DAERAH | C3: SASARAN DAERAH | D3: PROGRAM | E3: KEGIATAN PRIORITAS | F3: SASARAN KEGIATAN | G3: LOKASI (DESA/KEL) | I3: VOLUME | J3: PAGU USULAN AWAL | K3: PERANGKAT DAERAH PENANGGUNG JAWAB | L3: ID USULAN | M3: KECAMATAN | N3: HASIL PERBAIKAN KECAMATAN | P3: KETERANGAN | Q3: MENDUKUNG PILAR
G4: DESA | H4: DUSUN | N4: VOL | O4: PAGU
A5: 1 | B5: 2 | C5: 3 | D5: 4 | E5: 5 | F5: 6 | G5: 7 | H5: 8 | I5: 9 | J5: 10 | K5: 11 | L5: 12 | M5: 13 | N5: 14 | O5: 15 | P5: 16
A6: =A5+1 -> 2 | B6: Infrastruktur Berkelanjutan | C6: Meningkatnya Ketahanan Daerah terhadap Bencana | D6: PROGRAM PENANGGULANGAN BENCANA | E6: Pembangunan Sumur Bor | F6: Masyarakat Dusun Karang Duntal | G6: GERIMAX INDAH | H6: KARANG DUNTAL | I6: 1 unit | J6: 100000000 | K6: Badan Penanggulangan Bencana Daerah | L6: 2799328 | M6: Narmada | N6: 1 paket | O6: 210000000 | P6: Dilengkapi dengan usulan Proposal | Q6: Sosial dan Kelembagaan (Kapasitas Pemdes, Karang taruna, Perlindungan Sosial Komunitas)
A7: =A6+1 -> 3 | B7: Infrastruktur Berkelanjutan | C7: Meningkatnya Ketahanan Daerah terhadap Bencana | D7: PROGRAM PENANGGULANGAN BENCANA | E7: Pembangunan Sumur Bor | F7: Masyarakat Dusun Karang Anyar | G7: GERIMAX INDAH | H7: KARANG ANYAR (GERIMAX INDAH) | I7: 1 unit | J7: 100000000 | K7: Badan Penanggulangan Bencana Daerah | L7: 2799328 | M7: Narmada | N7: 1 paket | O7: 210000000 | P7: Dilengkapi dengan usulan Proposal | Q7: Sosial dan Kelembagaan (Kapasitas Pemdes, Karang taruna, Perlindungan Sosial Komunitas)
A8: =A7+1 -> 4 | B8: Infrastruktur Berkelanjutan | C8: Meningkatnya Ketahanan Daerah terhadap Bencana | D8: PROGRAM PENANGGULANGAN BENCANA | E8: PENANGGULANGAN BENCANA | F8: Pelatihan Relawan Kebencanaan | G8: Gerimax Indah | H8: =H3 -> 0 | I8: 1 Paket | J8: 7500000 | K8: Badan Penanggulangan Bencana Daerah | M8: Narmada | N8: 1 paket | O8: 35000000 | P8: Pindahan dari Pol PP | Q8: Sosial dan Kelembagaan (Kapasitas Pemdes, Karang taruna, Perlindungan Sosial Komunitas)
A9: =A8+1 -> 5 | B9: Infrastruktur Berkelanjutan | C9: Meningkatnya pembangunan Infrastruktur Dasar dan Konektivitas Antar Wilayah | D9: PROGRAM PENANGGULANGAN BENCANA | E9: PENGADAAN SUMUR BOR dan Intalasinya | F9: Masyarakat Dusun Lekong Siwak | G9: TANAK BEAK | H9: LEKONG SIWAK | I9: 1 | J9: 200000000 | K9: Badan Penanggulangan Bencana Daerah | L9: 2934710 | M9: Narmada | N9: 1 | O9: 210000000 | P9: sumur bor | Q9: Sosial dan Kelembagaan (Kapasitas Pemdes, Karang taruna, Perlindungan Sosial Komunitas)
